import { NextRequest, NextResponse } from 'next/server';
import { requireAuth } from '@/lib/auth';
import { AuthenticationError } from '@/lib/errors';

export async function GET(request: NextRequest) {
  const requestId = crypto.randomUUID();

  try {
    const user = await requireAuth(request);

    return NextResponse.json({
      success: true,
      data: {
        user: {
          id: user.id,
          email: user.email,
          fullName: user.fullName,
          role: user.role,
          isActive: user.isActive,
          createdAt: user.createdAt,
          lastLoginAt: user.lastLoginAt,
        },
      },
      meta: {
        timestamp: new Date().toISOString(),
        version: process.env.API_VERSION || '1.0',
        request_id: requestId,
      },
    });

  } catch (error) {
    if (error instanceof AuthenticationError) {
      return NextResponse.json({
        success: false,
        error: {
          code: error.code,
          message: error.message,
        },
        meta: {
          timestamp: new Date().toISOString(),
          request_id: requestId,
        },
      }, { status: error.statusCode });
    }

    console.error('Auth me error:', error);
    return NextResponse.json({
      success: false,
      error: {
        code: 'INTERNAL_ERROR',
        message: 'An unexpected error occurred',
      },
      meta: {
        timestamp: new Date().toISOString(),
        request_id: requestId,
      },
    }, { status: 500 });
  }
}